Workbook

Sheet 1. Dashboard
A1: SARS TAX YEAR 2025/2026 — TRACKING WORKBOOK
A2: The Process Enterprise (Pty) Ltd | Tax period: 1 March 2025 – 28 February 2026
A3: Account: ABSA Cheque 40-9656-3878 | Built from 12 monthly statements
A5: WORKBOOK GUIDE
A6: Sheet | B6: Purpose
A7: 1. Dashboard | B7: This page — high-level summary and tax savings calculation
A8: 2. Income Register | B8: All business income/revenue for the tax year
A9: 3. Expense Register | B9: Every expense transaction, tagged by category and deductibility
A10: 4. Category Summary | B10: Pivot of expenses by category — your tax deduction worksheet
A11: 5. Vehicle Logbook | B11: SARS-compliant vehicle logbook for Audi A4 (REQUIRED — fill in)
A12: 6. Asset Register | B12: Capital assets + wear-and-tear (depreciation) calculation
A13: 7. Trips & Travel | B13: Business trip register (entertainment, accommodation, flights)
A14: 8. Missing Receipts | B14: Items needing receipt reconstruction (you noted some are missing)
A15: 9. Tax Computation | B15: Final taxable income calculation and CIT (Corporate Tax) liability
A16: 10. SARS Checklist | B16: What to file, when, and what supporting docs are needed
A19: TAX YEAR AT A GLANCE
A20: Item | B20: Amount | C20: Source
A21: Total Business Income | B21: ='2. Income Register'!B2 -> 515904.84 | C21: From Income Register
A22: Total Operating Expenses (deductible) | B22: ='4. Category Summary'!E50 -> 376689.73 | C22: Sum of deductible expenses
A23: Wear-and-Tear (Depreciation) | B23: ='6. Asset Register'!H30 -> 75102.833 | C23: From Asset Register
A25: Net Taxable Income (before tax) | B25: =B21-B22-B23 -> 64112.277 | C25: Income - Expenses - Depreciation
A26: Corporate Income Tax (27%) | B26: =IF(B25>0,B25*0.27,0) -> 17310.315 | C26: SARS CIT rate FY 2025/26
A28: YOUR ESTIMATED TAX SAVINGS (vs no deductions) | B28: =(B22+B23)*0.27 -> 121983.99 | C28: Tax saved by claiming deductions
A31: ⚠ IMPORTANT NOTES
A32: 1. This workbook reads transactions from your ABSA Cheque account. Cash purchases or other accounts must be added manually to '3. Expense Register'.
A33: 2. Vehicle deductions REQUIRE a logbook (sheet 5). Without one, SARS may disallow ALL vehicle expenses.
A34: 3. Entertainment (client meals, dinners) is FULLY deductible for a Pty Ltd if it has a clear business purpose — but you must keep records of who you met and why.
A35: 4. Items marked 'Personal — Clothing' are NOT deductible unless they're protective gear or branded uniform.
A36: 5. Capital assets (laptops, iPhones, camera, vehicle) are NOT expensed — they are depreciated under the wear-and-tear allowance (s11(e)).
A37: 6. CIPC annual return + tax return (ITR14) due 12 months after year-end. First provisional tax was due 31 Aug 2025; second by 28 Feb 2026; top-up by 30 Sep 2026.
A38: 7. Keep ALL supporting docs (invoices, receipts, contracts) for 5 years per SARS rules.
A39: 8. For missing receipts: an affidavit + bank statement evidence may be accepted, but VAT input cannot be claimed without a proper tax invoice.

Sheet 2. Income Register
A1: INCOME REGISTER — Tax Year 2025/2026
A2: TOTAL INCOME (excl. internal transfers): | B2: =SUM(D5:D28) -> 515904.84
A4: Date | B4: Source / Customer | C4: Description | D4: Amount (R) | E4: Income Type | F4: Notes
A5: 45733 | B5: Platform Development | C5: Immediate Trf Cr Rand | Firstrand Nodods Platform Dev 05vl56h6cn | D5: 10000 | E5: Platform Development | F5: From bank statement
A6: 45741 | B6: AdSense / Google Revenue | C6: Acb Credit Settlement | Google Iregoogle Ireland | D6: 1881.15 | E6: AdSense / Google Revenue | F6: From bank statement
A7: 45748 | B7: Recruitment Services | C7: Immediate Trf Cr Ecbus | Capitecbussd Recruitment Ugngk7wv4b | D7: 18000 | E7: Recruitment Services | F7: From bank statement
A8: 45751 | B8: Platform Development | C8: Acb Credit Settlement | Nodods Platform Dev | D8: 5000 | E8: Platform Development | F8: From bank statement
A9: 45755 | B9: Recruitment Services | C9: Immediate Trf Cr Ecbus | Capitecbussd Recruitment 28n166km2j | D9: 18020 | E9: Recruitment Services | F9: From bank statement
A10: 45770 | B10: AdSense / Google Revenue | C10: Acb Credit Settlement | Google Iregoogle Ireland | D10: 4356.02 | E10: AdSense / Google Revenue | F10: From bank statement
A11: 45777 | B11: Platform Development | C11: Acb Credit Settlement | Nodods Holdings Stp | D11: 2000 | E11: Platform Development | F11: From bank statement
A12: 45782 | B12: Other Receipts | C12: Immediate Trf Cr Ecbus | Capitecbussdr Apr 2025 28wo0a8e9b | D12: 70400 | E12: Other Receipts | F12: From bank statement
A13: 45800 | B13: AdSense / Google Revenue | C13: Acb Credit Settlement | Google Iregoogle Ireland | D13: 1489.95 | E13: AdSense / Google Revenue | F13: From bank statement
A14: 45838 | B14: Platform Development | C14: Acb Credit Settlement | Nodods Platform Dev | D14: 2350 | E14: Platform Development | F14: From bank statement
A15: 45848 | B15: Recruitment Services | C15: Immediate Trf Cr Nk | Nedbank Sd Recruitment 2142862345 | D15: 74000 | E15: Recruitment Services | F15: From bank statement
A16: 45861 | B16: AdSense / Google Revenue | C16: Acb Credit Settlement | Google Iregoogle Ireland | D16: 1987.09 | E16: AdSense / Google Revenue | F16: From bank statement
... A28: 46080 | B28: Other Receipts | C28: Digital Payment Cr Settlement | Absa Bank Greencrate | D28: 4000 | E28: Other Receipts | F28: From bank statement
C29: TOTAL INCOME | D29: =SUM(D5:D28) -> 515904.84

Sheet 3. Expense Register
A1: EXPENSE REGISTER — Tax Year 2025/2026
A2: All expenses from ABSA Cheque 40-9656-3878. Use 'Deductible %' column to flag personal portions.
A4: Date | B4: Description | C4: Category | D4: Subcategory | E4: Amount (R) | F4: Charge (R) | G4: Deductible % | H4: Deductible (R) | I4: Receipt? (Y/N/Affidavit)
A5: 45717 | B5: Monthly Acc Fee Headoffice * | YOUR PRICING PLAN : BUSINESS ESSENTIALS LITE PACK | CREDIT INTEREST RATE AS AT 03/02/2025 STANDARD - REFER TO | C5: Bank Charges | D5: Bank Fees | E5: 200 | F5: 0 | G5: 1 | H5: =(E5+F5)*G5 -> 200 | I5: Bank statement only
A6: 45741 | B6: Payshap Ext Debit Settlement | Loan | C6: Loan Repayment | D6: Loan Repayment | E6: 2500 | F6: 7.5 | G6: 0 | H6: =(E6+F6)*G6 -> 0 | I6: Bank statement only
A7: 45741 | B7: Proof Of Pmt Email Settlement | C7: Bank Charges | D7: Bank Fees | E7: 0 | F7: 1.25 | G7: 1 | H7: =(E7+F7)*G7 -> 1.25
A8: 45741 | B8: Proof Of Paymt Sms Settlement | C8: Bank Charges | D8: Bank Fees | E8: 0 | F8: 1.25 | G8: 1 | H8: =(E8+F8)*G8 -> 1.25
A9: 45744 | B9: Digital Payment Dt Settlement | Absa Bank Loan | C9: Loan Repayment | D9: Loan Repayment | E9: 5000 | F9: 0 | G9: 0 | H9: =(E9+F9)*G9 -> 0 | I9: Bank statement only
A10: 45744 | B10: Proof Of Pmt Email Settlement | C10: Bank Charges | D10: Bank Fees | E10: 0 | F10: 1.25 | G10: 1 | H10: =(E10+F10)*G10 -> 1.25
A11: 45747 | B11: Digital Payment Dt Settlement | Absa Bank Domain Renewal | C11: Software/SaaS | D11: Domain Renewal | E11: 1000 | F11: 0 | G11: 1 | H11: =(E11+F11)*G11 -> 1000 | I11: Bank statement only
A12: 45747 | B12: Proof Of Pmt Email Settlement | C12: Bank Charges | D12: Bank Fees | E12: 0 | F12: 1.25 | G12: 1 | H12: =(E12+F12)*G12 -> 1.25
A13: 45748 | B13: Monthly Acc Fee Headoffice * | C13: Bank Charges | D13: Bank Fees | E13: 200 | F13: 0 | G13: 1 | H13: =(E13+F13)*G13 -> 200 | I13: Bank statement only
A14: 45748 | B14: Admin Charge Headoffice * | See Charge Statement Detail | C14: Bank Charges | D14: Bank Fees | E14: 15 | F14: 0 | G14: 1 | H14: =(E14+F14)*G14 -> 15 | I14: Bank statement only
A15: 45757 | B15: Payshap Ext Debit Settlement | Dinner Da | C15: Entertainment - Business | D15: Business Dinner | E15: 3000 | F15: 7.5 | G15: 1 | H15: =(E15+F15)*G15 -> 3007.5 | I15: Bank statement only
A16: 45757 | B16: Proof Of Pmt Email Settlement | C16: Bank Charges | D16: Bank Fees | E16: 0 | F16: 1.25 | G16: 1 | H16: =(E16+F16)*G16 -> 1.25
A17: 45757 | B17: Proof Of Paymt Sms Settlement | C17: Bank Charges | D17: Bank Fees | E17: 0 | F17: 1.25 | G17: 1 | H17: =(E17+F17)*G17 -> 1.25
A18: 45757 | B18: Payshap Ext Debit Settlement | Dinner Da | C18: Entertainment - Business | D18: Business Dinner | E18: 3000 | F18: 7.5 | G18: 1 | H18: =(E18+F18)*G18 -> 3007.5 | I18: Bank statement only
A19: 45757 | B19: Proof Of Pmt Email Settlement | C19: Bank Charges | D19: Bank Fees | E19: 0 | F19: 1.25 | G19: 1 | H19: =(E19+F19)*G19 -> 1.25
A20: 45757 | B20: Proof Of Paymt Sms Settlement | C20: Bank Charges | D20: Bank Fees | E20: 0 | F20: 1.25 | G20: 1 | H20: =(E20+F20)*G20 -> 1.25
A21: 45757 | B21: Payshap Ext Debit Settlement | Dinner With Da | C21: Entertainment - Business | D21: Business Dinner | E21: 3000 | F21: 7.5 | G21: 1 | H21: =(E21+F21)*G21 -> 3007.5 | I21: Bank statement only
A22: 45757 | B22: Proof Of Pmt Email Settlement | C22: Bank Charges | D22: Bank Fees | E22: 0 | F22: 1.25 | G22: 1 | H22: =(E22+F22)*G22 -> 1.25
A23: 45757 | B23: Proof Of Paymt Sms Settlement | C23: Bank Charges | D23: Bank Fees | E23: 0 | F23: 1.25 | G23: 1 | H23: =(E23+F23)*G23 -> 1.25
A24: 45757 | B24: Payshap Ext Debit Settlement | Dinner With Da | C24: Entertainment - Business | D24: Business Dinner | E24: 1000 | F24: 7.5 | G24: 1 | H24: =(E24+F24)*G24 -> 1007.5 | I24: Bank statement only
A25: 45757 | B25: Proof Of Pmt Email Settlement | C25: Bank Charges | D25: Bank Fees | E25: 0 | F25: 1.25 | G25: 1 | H25: =(E25+F25)*G25 -> 1.25
A26: 45757 | B26: Proof Of Paymt Sms Settlement | C26: Bank Charges | D26: Bank Fees | E26: 0 | F26: 1.25 | G26: 1 | H26: =(E26+F26)*G26 -> 1.25
A27: 45758 | B27: Payshap Ext Debit Settlement | Dinner With Da | C27: Entertainment - Business | D27: Business Dinner | E27: 3000 | F27: 7.5 | G27: 1 | H27: =(E27+F27)*G27 -> 3007.5 | I27: Bank statement only
A28: 45758 | B28: Proof Of Pmt Email Settlement | C28: Bank Charges | D28: Bank Fees | E28: 0 | F28: 1.25 | G28: 1 | H28: =(E28+F28)*G28 -> 1.25
A29: 45758 | B29: Proof Of Paymt Sms Settlement | C29: Bank Charges | D29: Bank Fees | E29: 0 | F29: 1.25 | G29: 1 | H29: =(E29+F29)*G29 -> 1.25
A30: 45758 | B30: Payshap Ext Debit Settlement | C30: Other - Review | D30: PayShap (review) | E30: 1000 | F30: 7.5 | G30: 0.5 | H30: =(E30+F30)*G30 -> 503.75 | I30: Bank statement only
A31: 45758 | B31: Proof Of Pmt Email Settlement | C31: Bank Charges | D31: Bank Fees | E31: 0 | F31: 1.25 | G31: 1 | H31: =(E31+F31)*G31 -> 1.25
A32: 45758 | B32: Proof Of Paymt Sms Settlement | C32: Bank Charges | D32: Bank Fees | E32: 0 | F32: 1.25 | G32: 1 | H32: =(E32+F32)*G32 -> 1.25
A33: 45759 | B33: Payshap Ext Debit Settlement | Travel+tire | C33: Vehicle - Maintenance | D33: Audi A4 Repairs/Service | E33: 3000 | F33: 7.5 | G33: 1 | H33: =(E33+F33)*G33 -> 3007.5 | I33: Bank statement only
A34: 45759 | B34: Proof Of Pmt Email Settlement | C34: Bank Charges | D34: Bank Fees | E34: 0 | F34: 1.25 | G34: 1 | H34: =(E34+F34)*G34 -> 1.25
A35: 45759 | B35: Proof Of Paymt Sms Settlement | C35: Bank Charges | D35: Bank Fees | E35: 0 | F35: 1.25 | G35: 1 | H35: =(E35+F35)*G35 -> 1.25
A36: 45759 | B36: Payshap Ext Debit Settlement | Travel+tire | C36: Vehicle - Maintenance | D36: Audi A4 Repairs/Service | E36: 1500 | F36: 7.5 | G36: 1 | H36: =(E36+F36)*G36 -> 1507.5 | I36: Bank statement only
A37: 45759 | B37: Proof Of Pmt Email Settlement | C37: Bank Charges | D37: Bank Fees | E37: 0 | F37: 1.25 | G37: 1 | H37: =(E37+F37)*G37 -> 1.25
A38: 45759 | B38: Proof Of Paymt Sms Settlement | C38: Bank Charges | D38: Bank Fees | E38: 0 | F38: 1.25 | G38: 1 | H38: =(E38+F38)*G38 -> 1.25
A39: 45762 | B39: Payshap Ext Debit Settlement | Dinner With Da | C39: Entertainment - Business | D39: Business Dinner | E39: 3000 | F39: 7.5 | G39: 1 | H39: =(E39+F39)*G39 -> 3007.5 | I39: Bank statement only
A40: 45762 | B40: Proof Of Pmt Email Settlement | C40: Bank Charges | D40: Bank Fees | E40: 0 | F40: 1.25 | G40: 1 | H40: =(E40+F40)*G40 -> 1.25
A41: 45762 | B41: Proof Of Paymt Sms Settlement | C41: Bank Charges | D41: Bank Fees | E41: 0 | F41: 1.25 | G41: 1 | H41: =(E41+F41)*G41 -> 1.25
...

Sheet 4. Category Summary
A1: EXPENSE CATEGORY SUMMARY — Deduction Worksheet
A2: Aggregated by category. The 'Total Deductible' column drives your tax computation.
A4: Category | B4: Count | C4: Gross Amount (R) | D4: Charges (R) | E4: Total Deductible (R) | F4: Tax Treatment Notes
A5: Vehicle - Fuel | B5: =COUNTIF('3. Expense Register'!C5:C354,A5) -> 17 | C5: =SUMIF('3. Expense Register'!C5:C354,A5,'3. Expense Register'!E5:E354) -> 2792.2 | D5: =SUMIF('3. Expense Register'!C5:C354,A5,'3. Expense Register'!F5:F354) -> 24 | E5: =SUMIF('3. Expense Register'!C5:C354,A5,'3. Expense Register'!H5:H354) -> 2816.2 | F5: Deductible PRO-RATA based on business km % from logbook (s11(a))
A6: Vehicle - Maintenance | B6: =COUNTIF('3. Expense Register'!C5:C354,A6) -> 38 | C6: =SUMIF('3. Expense Register'!C5:C354,A6,'3. Expense Register'!E5:E354) -> 144591.2 | D6: =SUMIF('3. Expense Register'!C5:C354,A6,'3. Expense Register'!F5:F354) -> 268 | E6: =SUMIF('3. Expense Register'!C5:C354,A6,'3. Expense Register'!H5:H354) -> 144859.2 | F6: Deductible PRO-RATA based on business km % from logbook (s11(d))
A7: Vehicle - Licensing | B7: =COUNTIF('3. Expense Register'!C5:C354,A7) -> 4 | C7: =SUMIF('3. Expense Register'!C5:C354,A7,'3. Expense Register'!E5:E354) -> 6350 | D7: =SUMIF('3. Expense Register'!C5:C354,A7,'3. Expense Register'!F5:F354) -> 30 | E7: =SUMIF('3. Expense Register'!C5:C354,A7,'3. Expense Register'!H5:H354) -> 6380 | F7: Deductible PRO-RATA based on business km % from logbook
A8: Travel - Local | B8: =COUNTIF('3. Expense Register'!C5:C354,A8) -> 61 | C8: =SUMIF('3. Expense Register'!C5:C354,A8,'3. Expense Register'!E5:E354) -> 17279 | D8: =SUMIF('3. Expense Register'!C5:C354,A8,'3. Expense Register'!F5:F354) -> 255.5 | E8: =SUMIF('3. Expense Register'!C5:C354,A8,'3. Expense Register'!H5:H354) -> 17534.5 | F8: Fully deductible if for business purpose (Uber, taxi)
A9: Travel - Air | B9: =COUNTIF('3. Expense Register'!C5:C354,A9) -> 0 | C9: =SUMIF('3. Expense Register'!C5:C354,A9,'3. Expense Register'!E5:E354) -> 0 | D9: =SUMIF('3. Expense Register'!C5:C354,A9,'3. Expense Register'!F5:F354) -> 0 | E9: =SUMIF('3. Expense Register'!C5:C354,A9,'3. Expense Register'!H5:H354) -> 0 | F9: Fully deductible — keep boarding pass + invoice
A10: Travel - Accommodation | B10: =COUNTIF('3. Expense Register'!C5:C354,A10) -> 0 | C10: =SUMIF('3. Expense Register'!C5:C354,A10,'3. Expense Register'!E5:E354) -> 0 | D10: =SUMIF('3. Expense Register'!C5:C354,A10,'3. Expense Register'!F5:F354) -> 0 | E10: =SUMIF('3. Expense Register'!C5:C354,A10,'3. Expense Register'!H5:H354) -> 0 | F10: Fully deductible — keep tax invoice
A11: Meals - Business | B11: =COUNTIF('3. Expense Register'!C5:C354,A11) -> 5 | C11: =SUMIF('3. Expense Register'!C5:C354,A11,'3. Expense Register'!E5:E354) -> 2233.43 | D11: =SUMIF('3. Expense Register'!C5:C354,A11,'3. Expense Register'!F5:F354) -> 0 | E11: =SUMIF('3. Expense Register'!C5:C354,A11,'3. Expense Register'!H5:H354) -> 2233.43 | F11: Deductible IF for business purpose with records of who/why
A12: Entertainment - Business | B12: =COUNTIF('3. Expense Register'!C5:C354,A12) -> 12 | C12: =SUMIF('3. Expense Register'!C5:C354,A12,'3. Expense Register'!E5:E354) -> 30500 | D12: =SUMIF('3. Expense Register'!C5:C354,A12,'3. Expense Register'!F5:F354) -> 90 | E12: =SUMIF('3. Expense Register'!C5:C354,A12,'3. Expense Register'!H5:H354) -> 30590 | F12: Deductible if business meeting documented (s11(a))
A13: Software/SaaS | B13: =COUNTIF('3. Expense Register'!C5:C354,A13) -> 16 | C13: =SUMIF('3. Expense Register'!C5:C354,A13,'3. Expense Register'!E5:E354) -> 21551.88 | D13: =SUMIF('3. Expense Register'!C5:C354,A13,'3. Expense Register'!F5:F354) -> 96.62 | E13: =SUMIF('3. Expense Register'!C5:C354,A13,'3. Expense Register'!H5:H354) -> 21648.5 | F13: 100% deductible as operating expense
A14: Equipment - Office | B14: =COUNTIF('3. Expense Register'!C5:C354,A14) -> 1 | C14: =SUMIF('3. Expense Register'!C5:C354,A14,'3. Expense Register'!E5:E354) -> 2395 | D14: =SUMIF('3. Expense Register'!C5:C354,A14,'3. Expense Register'!F5:F354) -> 0 | E14: =SUMIF('3. Expense Register'!C5:C354,A14,'3. Expense Register'!H5:H354) -> 2395 | F14: If <R7,000 immediately deductible; if >R7,000 capitalise
A15: Equipment - IT | B15: =COUNTIF('3. Expense Register'!C5:C354,A15) -> 1 | C15: =SUMIF('3. Expense Register'!C5:C354,A15,'3. Expense Register'!E5:E354) -> 19999 | D15: =SUMIF('3. Expense Register'!C5:C354,A15,'3. Expense Register'!F5:F354) -> 0 | E15: =SUMIF('3. Expense Register'!C5:C354,A15,'3. Expense Register'!H5:H354) -> 0 | F15: CAPITAL — depreciate via wear-and-tear over 3 yrs (s11(e))
A16: Equipment - Camera/Photo | B16: =COUNTIF('3. Expense Register'!C5:C354,A16) -> 4 | C16: =SUMIF('3. Expense Register'!C5:C354,A16,'3. Expense Register'!E5:E354) -> 32945 | D16: =SUMIF('3. Expense Register'!C5:C354,A16,'3. Expense Register'!F5:F354) -> 16 | E16: =SUMIF('3. Expense Register'!C5:C354,A16,'3. Expense Register'!H5:H354) -> 0 | F16: CAPITAL — depreciate via wear-and-tear over 6 yrs (s11(e))
A17: Office - Refreshments | B17: =COUNTIF('3. Expense Register'!C5:C354,A17) -> 6 | C17: =SUMIF('3. Expense Register'!C5:C354,A17,'3. Expense Register'!E5:E354) -> 1730.41 | D17: =SUMIF('3. Expense Register'!C5:C354,A17,'3. Expense Register'!F5:F354) -> 8 | E17: =SUMIF('3. Expense Register'!C5:C354,A17,'3. Expense Register'!H5:H354) -> 1738.41 | F17: Deductible if for staff/clients in business context
A18: Office - General | B18: =COUNTIF('3. Expense Register'!C5:C354,A18) -> 1 | C18: =SUMIF('3. Expense Register'!C5:C354,A18,'3. Expense Register'!E5:E354) -> 1399 | D18: =SUMIF('3. Expense Register'!C5:C354,A18,'3. Expense Register'!F5:F354) -> 8 | E18: =SUMIF('3. Expense Register'!C5:C354,A18,'3. Expense Register'!H5:H354) -> 1407 | F18: Deductible if business-related
A19: Compliance | B19: =COUNTIF('3. Expense Register'!C5:C354,A19) -> 1 | C19: =SUMIF('3. Expense Register'!C5:C354,A19,'3. Expense Register'!E5:E354) -> 100 | D19: =SUMIF('3. Expense Register'!C5:C354,A19,'3. Expense Register'!F5:F354) -> 0 | E19: =SUMIF('3. Expense Register'!C5:C354,A19,'3. Expense Register'!H5:H354) -> 100 | F19: Fully deductible (CIPC, regulatory fees)
A20: Professional Fees | B20: =COUNTIF('3. Expense Register'!C5:C354,A20) -> 4 | C20: =SUMIF('3. Expense Register'!C5:C354,A20,'3. Expense Register'!E5:E354) -> 12000 | D20: =SUMIF('3. Expense Register'!C5:C354,A20,'3. Expense Register'!F5:F354) -> 33 | E20: =SUMIF('3. Expense Register'!C5:C354,A20,'3. Expense Register'!H5:H354) -> 12033 | F20: Fully deductible (legal, accounting, audit)
A21: Bank Charges | B21: =COUNTIF('3. Expense Register'!C5:C354,A21) -> 124 | C21: =SUMIF('3. Expense Register'!C5:C354,A21,'3. Expense Register'!E5:E354) -> 3484.93 | D21: =SUMIF('3. Expense Register'!C5:C354,A21,'3. Expense Register'!F5:F354) -> 130.5 | E21: =SUMIF('3. Expense Register'!C5:C354,A21,'3. Expense Register'!H5:H354) -> 3615.43 | F21: 100% deductible operating expense
A22: Director Remuneration | B22: =COUNTIF('3. Expense Register'!C5:C354,A22) -> 1 | C22: =SUMIF('3. Expense Register'!C5:C354,A22,'3. Expense Register'!E5:E354) -> 25000 | D22: =SUMIF('3. Expense Register'!C5:C354,A22,'3. Expense Register'!F5:F354) -> 40 | E22: =SUMIF('3. Expense Register'!C5:C354,A22,'3. Expense Register'!H5:H354) -> 25040 | F22: Fully deductible BUT must be on PAYE; declare on EMP201/EMP501
A23: Staff Costs - Stipend | B23: =COUNTIF('3. Expense Register'!C5:C354,A23) -> 11 | C23: =SUMIF('3. Expense Register'!C5:C354,A23,'3. Expense Register'!E5:E354) -> 86000 | D23: =SUMIF('3. Expense Register'!C5:C354,A23,'3. Expense Register'!F5:F354) -> 61.5 | E23: =SUMIF('3. Expense Register'!C5:C354,A23,'3. Expense Register'!H5:H354) -> 86061.5 | F23: Deductible BUT review whether IRP5 needed if regular employees
A24: Staff Costs - Benefits | B24: =COUNTIF('3. Expense Register'!C5:C354,A24) -> 1 | C24: =SUMIF('3. Expense Register'!C5:C354,A24,'3. Expense Register'!E5:E354) -> 7095 | D24: =SUMIF('3. Expense Register'!C5:C354,A24,'3. Expense Register'!F5:F354) -> 0 | E24: =SUMIF('3. Expense Register'!C5:C354,A24,'3. Expense Register'!H5:H354) -> 7095 | F24: Deductible (medical aid, etc.)
A25: Staff Costs - Training | B25: =COUNTIF('3. Expense Register'!C5:C354,A25) -> 1 | C25: =SUMIF('3. Expense Register'!C5:C354,A25,'3. Expense Register'!E5:E354) -> 1500 | D25: =SUMIF('3. Expense Register'!C5:C354,A25,'3. Expense Register'!F5:F354) -> 7.5 | E25: =SUMIF('3. Expense Register'!C5:C354,A25,'3. Expense Register'!H5:H354) -> 1507.5 | F25: Fully deductible — Learnership allowance may apply (s12H)
A26: Staff Costs - Reimbursement | B26: =COUNTIF('3. Expense Register'!C5:C354,A26) -> 1 | C26: =SUMIF('3. Expense Register'!C5:C354,A26,'3. Expense Register'!E5:E354) -> 1800 | D26: =SUMIF('3. Expense Register'!C5:C354,A26,'3. Expense Register'!F5:F354) -> 7.5 | E26: =SUMIF('3. Expense Register'!C5:C354,A26,'3. Expense Register'!H5:H354) -> 1807.5 | F26: Deductible if actual business expense reimbursed
A27: Personal - Clothing | B27: =COUNTIF('3. Expense Register'!C5:C354,A27) -> 1 | C27: =SUMIF('3. Expense Register'!C5:C354,A27,'3. Expense Register'!E5:E354) -> 1543 | D27: =SUMIF('3. Expense Register'!C5:C354,A27,'3. Expense Register'!F5:F354) -> 8 | E27: =SUMIF('3. Expense Register'!C5:C354,A27,'3. Expense Register'!H5:H354) -> 0 | F27: NOT deductible unless protective/branded uniform
A28: Loan Repayment | B28: =COUNTIF('3. Expense Register'!C5:C354,A28) -> 5 | C28: =SUMIF('3. Expense Register'!C5:C354,A28,'3. Expense Register'!E5:E354) -> 65500 | D28: =SUMIF('3. Expense Register'!C5:C354,A28,'3. Expense Register'!F5:F354) -> 15 | E28: =SUMIF('3. Expense Register'!C5:C354,A28,'3. Expense Register'!H5:H354) -> 0 | F28: PRINCIPAL not deductible; interest portion deductible
A29: Refund | B29: =COUNTIF('3. Expense Register'!C5:C354,A29) -> 2 | C29: =SUMIF('3. Expense Register'!C5:C354,A29,'3. Expense Register'!E5:E354) -> 4050 | D29: =SUMIF('3. Expense Register'!C5:C354,A29,'3. Expense Register'!F5:F354) -> 0 | E29: =SUMIF('3. Expense Register'!C5:C354,A29,'3. Expense Register'!H5:H354) -> 0 | F29: Reduces income, not an expense
A30: Other - Review | B30: =COUNTIF('3. Expense Register'!C5:C354,A30) -> 27 | C30: =SUMIF('3. Expense Register'!C5:C354,A30,'3. Expense Register'!E5:E354) -> 15506.12 | D30: =SUMIF('3. Expense Register'!C5:C354,A30,'3. Expense Register'!F5:F354) -> 149 | E30: =SUMIF('3. Expense Register'!C5:C354,A30,'3. Expense Register'!H5:H354) -> 7827.56 | F30: NEEDS REVIEW — manually classify each item
A31: Transfer Out | B31: =COUNTIF('3. Expense Register'!C5:C354,A31) -> 5 | C31: =SUMIF('3. Expense Register'!C5:C354,A31,'3. Expense Register'!E5:E354) -> 291000 | D31: =SUMIF('3. Expense Register'!C5:C354,A31,'3. Expense Register'!F5:F354) -> 0 | E31: =SUMIF('3. Expense Register'!C5:C354,A31,'3. Expense Register'!H5:H354) -> 0 | F31: Inter-account transfer — NOT an expense
A50: TOTAL DEDUCTIBLE OPERATING EXPENSES | B50: =SUM(B5:B49) -> 350 | C50: =SUM(C5:C49) -> 798345.17 | D50: =SUM(D5:D49) -> 1248.12 | E50: =SUM(E5:E49) -> 376689.73

Sheet 5. Vehicle Logbook
A1: AUDI A4 BUSINESS VEHICLE LOGBOOK — SARS Compliant
A2: REQUIRED to claim ANY vehicle deduction. Without this, SARS disallows fuel/maintenance/licensing.
A4: Vehicle: | B4: Audi A4 (Business)
A5: Owner: | B5: The Process Enterprise (Pty) Ltd
A6: Period: | B6: 1 March 2025 – 28 February 2026
A7: Opening Odometer (1 March 2025): | B7: FILL IN
A8: Closing Odometer (28 Feb 2026): | B8: FILL IN
A9: Total km traveled (calculated): | B9: =IF(AND(ISNUMBER(B7),ISNUMBER(B8)),B8-B7,"Fill odometer readings") -> Fill odometer readings
A11: Date | B11: From | C11: To | D11: Purpose / Client / Notes | E11: Start km | F11: End km | G11: Distance (km) | H11: Business / Private
G12: =IF(AND(ISNUMBER(E12),ISNUMBER(F12)),F12-E12,"")
G13: =IF(AND(ISNUMBER(E13),ISNUMBER(F13)),F13-E13,"")
G14: =IF(AND(ISNUMBER(E14),ISNUMBER(F14)),F14-E14,"")
G15: =IF(AND(ISNUMBER(E15),ISNUMBER(F15)),F15-E15,"")
G16: =IF(AND(ISNUMBER(E16),ISNUMBER(F16)),F16-E16,"")
G17: =IF(AND(ISNUMBER(E17),ISNUMBER(F17)),F17-E17,"")
G18: =IF(AND(ISNUMBER(E18),ISNUMBER(F18)),F18-E18,"")
G19: =IF(AND(ISNUMBER(E19),ISNUMBER(F19)),F19-E19,"")
G20: =IF(AND(ISNUMBER(E20),ISNUMBER(F20)),F20-E20,"")
G21: =IF(AND(ISNUMBER(E21),ISNUMBER(F21)),F21-E21,"")
G22: =IF(AND(ISNUMBER(E22),ISNUMBER(F22)),F22-E22,"")
G23: =IF(AND(ISNUMBER(E23),ISNUMBER(F23)),F23-E23,"")
... G111: =IF(AND(ISNUMBER(E111),ISNUMBER(F111)),F111-E111,"")
A114: LOGBOOK SUMMARY
A115: Total Business km: | B115: =SUMIF(H12:H111,"Business",G12:G111) -> 0
A116: Total Private km: | B116: =SUMIF(H12:H111,"Private",G12:G111) -> 0
A117: Total km logged: | B117: =B115+B116 -> 0
A118: Business use %: | B118: =IF(B117>0,B115/B117,0) -> 0
A120: → Apply this % to Vehicle Fuel/Maintenance/Licensing in '3. Expense Register' (column G)

Sheet 6. Asset Register
A1: ASSET REGISTER & WEAR-AND-TEAR (DEPRECIATION) — s11(e)
A2: SARS Interpretation Note 47: write-off periods. Capital assets are deducted via wear-and-tear, not as expenses.
A4: # | B4: Asset Description | C4: Date Acquired | D4: Cost (R) | E4: Useful Life (Yrs) | F4: Annual Wear-and-Tear (R) | G4: % Business Use | H4: Deductible W&T (R)
A5: 1 | B5: iPhone 12 (Business) | C5: 2025-03-01 | D5: 11999 | E5: 3 | F5: =IF(E5>0,D5/E5,0) -> 3999.6667 | G5: 1 | H5: =F5*G5 -> 3999.6667
A6: 2 | B6: iPhone 14 Pro (Business) | C6: 2025-03-01 | D6: 17999 | E6: 3 | F6: =IF(E6>0,D6/E6,0) -> 5999.6667 | G6: 1 | H6: =F6*G6 -> 5999.6667
A7: 3 | B7: Work Laptop #1 | C7: 2025-03-01 | D7: 25000 | E7: 3 | F7: =IF(E7>0,D7/E7,0) -> 8333.3333 | G7: 1 | H7: =F7*G7 -> 8333.3333
A8: 4 | B8: Work Laptop #2 | C8: 2025-03-01 | D8: 18000 | E8: 3 | F8: =IF(E8>0,D8/E8,0) -> 6000 | G8: 1 | H8: =F8*G8 -> 6000
A9: 5 | B9: Sony Camera | C9: 45975 | D9: 29999 | E9: 6 | F9: =IF(E9>0,D9/E9,0) -> 4999.8333 | G9: 1 | H9: =F9*G9 -> 4999.8333
A10: 6 | B10: Audi A4 Vehicle | C10: 2025-03-01 | D10: 185000 | E10: 5 | F10: =IF(E10>0,D10/E10,0) -> 37000 | G10: 0.9 | H10: =F10*G10 -> 33300
A11: 7 | B11: Camera/Photo Equipment (Cinephoto purchases) | C11: 2026-01-24 | D11: 22765 | E11: 6 | F11: =IF(E11>0,D11/E11,0) -> 3794.1667 | G11: 1 | H11: =F11*G11 -> 3794.1667
A12: 8 | B12: Camera Equipment (Cameraworld) | C12: 2025-11-14 | D12: 6190 | E12: 6 | F12: =IF(E12>0,D12/E12,0) -> 1031.6667 | G12: 1 | H12: =F12*G12 -> 1031.6667
A13: 9 | B13: Camera Equipment (Cinephoto Nov) | C13: 2025-11-16 | D13: 2995 | E13: 6 | F13: =IF(E13>0,D13/E13,0) -> 499.16667 | G13: 1 | H13: =F13*G13 -> 499.16667
A14: 10 | B14: 3D Printer (Payfast / Netram) | C14: 2025-12-11 | D14: 19999 | E14: 3 | F14: =IF(E14>0,D14/E14,0) -> 6666.3333 | G14: 1 | H14: =F14*G14 -> 6666.3333
A15: 11 | B15: Speaker/Monitor | C15: 2025-07-08 | D15: 2395 | E15: 5 | F15: =IF(E15>0,D15/E15,0) -> 479 | G15: 1 | H15: =F15*G15 -> 479
A30: TOTAL | D30: =SUM(D5:D29) -> 342341 | F30: =SUM(F5:F29) -> 78802.833 | H30: =SUM(H5:H29) -> 75102.833
A33: SARS WRITE-OFF PERIODS (Interpretation Note 47, Annexure A):
A34: • Computers: 3 years
A35: • Cell phones: 2 years (we used 3 conservatively)
A36: • Cameras (photographic equipment): 6 years
A37: • Motor vehicles (passenger): 5 years
A38: • Furniture & fittings: 6 years
A39: • Section 12C: NEW manufacturing assets — accelerated 40/20/20/20
A40: • Small items <R7,000: can be expensed in full (s11(e) proviso)

Sheet 7. Trips & Travel
A1: BUSINESS TRIPS & TRAVEL REGISTER
A2: Document each business trip with purpose. Required for SARS to allow travel/entertainment deductions.
A4: Trip # | B4: Date(s) | C4: Destination | D4: Purpose / Client | E4: People Met | F4: Travel Cost (R) | G4: Accommodation (R) | H4: Meals/Entertainment (R)
A5: 1 | B5: 2025-04-10 to 11 | C5: Cape Town | D5: Client dinner — DA (multiple meetings) | E5: DA (fill in full name & company) | F5: 0 | G5: 0 | H5: 14000
A6: 2 | B6: 2025-04-15 | C6: Cape Town | D6: Client meeting — DA | E6: DA (fill in) | F6: 0 | G6: 0 | H6: 6000
A7: 3 | B7: 2025-04-12 | C7: Cape Town | D7: Travel + tire (review purpose) | E7: Fill in | F7: 4500 | G7: 0 | H7: 0
A8: 4 | B8: Fill in | C8: Fill in | D8: Fill in | E8: Fill in | F8: 0 | G8: 0 | H8: 0
A9: 5 | B9: Fill in | C9: Fill in | D9: Fill in | E9: Fill in | F9: 0 | G9: 0 | H9: 0
A10: 6 | B10: Fill in | C10: Fill in | D10: Fill in | E10: Fill in | F10: 0 | G10: 0 | H10: 0
A11: 7 | B11: Fill in | C11: Fill in | D11: Fill in | E11: Fill in | F11: 0 | G11: 0 | H11: 0
A12: 8 | B12: Fill in | C12: Fill in | D12: Fill in | E12: Fill in | F12: 0 | G12: 0 | H12: 0
A13: 9 | B13: Fill in | C13: Fill in | D13: Fill in | E13: Fill in | F13: 0 | G13: 0 | H13: 0
A14: 10 | B14: Fill in | C14: Fill in | D14: Fill in | E14: Fill in | F14: 0 | G14: 0 | H14: 0
D16: TOTAL TRIPS | F16: =SUM(F5:F15) -> 4500 | G16: =SUM(G5:G15) -> 0 | H16: =SUM(H5:H15) -> 20000

Sheet 8. Missing Receipts
A1: MISSING RECEIPTS LOG
A2: For receipts you don't have: prepare an affidavit + bank statement to support the expense. VAT input cannot be claimed without a valid tax invoice.
A4: Date | B4: Description | C4: Amount (R) | D4: Reason Receipt Missing | E4: Supporting Evidence Available | F4: Affidavit Done? (Y/N)
A5: 46072 | B5: Pos Purchase Settlement | Card No. 7884 Used Car Parts Kraai | (Effective 17/02/ | C5: 31000 | D5: Fill in (e.g., 'lost', 'never received') | E5: Bank statement entry | F5: N
A6: 45808 | B6: Imdte Digital Pmt Settlement | Absa Bank Salary 16191440b5 | C6: 25000 | D6: Fill in (e.g., 'lost', 'never received') | E6: Bank statement entry | F6: N
A7: 45927 | B7: Imdte Digital Pmt Settlement | Absa Bank Audi A4 1619985588 | C7: 25000 | D7: Fill in (e.g., 'lost', 'never received') | E7: Bank statement entry | F7: N
A8: 45927 | B8: Imdte Digital Pmt Settlement | Absa Bank Audi A4 16199855c2 | C8: 25000 | D8: Fill in (e.g., 'lost', 'never received') | E8: Bank statement entry | F8: N
A9: 45927 | B9: Imdte Digital Pmt Settlement | Absa Bank Audi A4 16199855e0 | C9: 25000 | D9: Fill in (e.g., 'lost', 'never received') | E9: Bank statement entry | F9: N
A10: 46046 | B10: Pos Purchase Settlement | Card No. 7884 Cinephoto Tools Cpt Cape | (Effective 21 | C10: 22765 | D10: Fill in (e.g., 'lost', 'never received') | E10: Bank statement entry | F10: N
A11: 46002 | B11: Pos Purchase Settlement | Card No. 7884 Payfast *Netram El Cape | (Effective 10/ | C11: 19999 | D11: Fill in (e.g., 'lost', 'never received') | E11: Bank statement entry | F11: N
A12: 46045 | B12: Digital Payment Dt Settlement | Absa Bank Stipend | C12: 18000 | D12: Fill in (e.g., 'lost', 'never received') | E12: Bank statement entry | F12: N
A13: 45983 | B13: Digital Payment Dt Settlement | Absa Bank Visa | C13: 12000 | D13: Fill in (e.g., 'lost', 'never received') | E13: Bank statement entry | F13: N
A14: 45927 | B14: Imdte Digital Pmt Settlement | Absa Bank Audi A4 1619985609 | C14: 10000 | D14: Fill in (e.g., 'lost', 'never received') | E14: Bank statement entry | F14: N
A15: 46013 | B15: Digital Payment Dt Settlement | Absa Bank Nkosinathi Vonco | C15: 10000 | D15: Fill in (e.g., 'lost', 'never received') | E15: Bank statement entry | F15: N
A16: 45772 | B16: Digital Payment Dt Settlement | Absa Bank Rhythmstarr | C16: 7700 | D16: Fill in (e.g., 'lost', 'never received') | E16: Bank statement entry | F16: N
... A28: 45964 | B28: Digital Payment Dt Settlement | Absa Bank Stipend | C28: 6000 | D28: Fill in (e.g., 'lost', 'never received') | E28: Bank statement entry | F28: N

Sheet 9. Tax Computation
A1: CORPORATE TAX COMPUTATION — Year of Assessment 2026
A2: The Process Enterprise (Pty) Ltd — Year ended 28 February 2026
A4: Description | B4: Amount (R) | C4: Notes | D4: Reference
A5: INCOME
A6: Gross Business Income | B6: ='2. Income Register'!B2 -> 515904.84 | C6: From Income Register
A7: Less: Refunds Issued | B7: =-SUMIF('3. Expense Register'!C5:C354,"Refund",'3. Expense Register'!E5:E354) -> -4050 | C7: Customer refunds
A8: NET INCOME | B8: =B6+B7 -> 511854.84
A10: LESS: DEDUCTIBLE OPERATING EXPENSES
A11: Vehicle - Fuel | B11: =SUMIF('4. Category Summary'!A5:A49,"Vehicle - Fuel",'4. Category Summary'!E5:E49) -> 2816.2 | C11: Pro-rata business %
A12: Vehicle - Maintenance | B12: =SUMIF('4. Category Summary'!A5:A49,"Vehicle - Maintenance",'4. Category Summary'!E5:E49) -> 144859.2 | C12: Pro-rata business %
A13: Vehicle - Licensing | B13: =SUMIF('4. Category Summary'!A5:A49,"Vehicle - Licensing",'4. Category Summary'!E5:E49) -> 6380 | C13: Pro-rata business %
A14: Travel - Local (Uber etc.) | B14: =SUMIF('4. Category Summary'!A5:A49,"Travel - Local",'4. Category Summary'!E5:E49) -> 17534.5
A15: Travel - Air & Accommodation | B15: =SUMIF('4. Category Summary'!A5:A49,"Travel - Air",'4. Category Summary'!E5:E49)+SUMIF('4. Category Summary'!A5:A49,"Travel - Accommodation",'4. Category Summary'!E5:E49) -> 0
A16: Meals & Entertainment | B16: =SUMIF('4. Category Summary'!A5:A49,"Meals - Business",'4. Category Summary'!E5:E49)+SUMIF('4. Category Summary'!A5:A49,"Entertainment - Business",'4. Category Summary'!E5:E49) -> 32823.43 | C16: Must have business purpose docs
A17: Software & SaaS | B17: =SUMIF('4. Category Summary'!A5:A49,"Software/SaaS",'4. Category Summary'!E5:E49) -> 21648.5
A18: Office Equipment (small) | B18: =SUMIF('4. Category Summary'!A5:A49,"Equipment - Office",'4. Category Summary'!E5:E49)+SUMIF('4. Category Summary'!A5:A49,"Office - Refreshments",'4. Category Summary'!E5:E49)+SUMIF('4. Category Summary'!A5:A49,"Office - General",'4. Category Summary'!E5:E49) -> 5540.41
A19: Compliance & Professional Fees | B19: =SUMIF('4. Category Summary'!A5:A49,"Compliance",'4. Category Summary'!E5:E49)+SUMIF('4. Category Summary'!A5:A49,"Professional Fees",'4. Category Summary'!E5:E49) -> 12133 | C19: CIPC, legal, accounting
A20: Bank Charges | B20: =SUMIF('4. Category Summary'!A5:A49,"Bank Charges",'4. Category Summary'!E5:E49) -> 3615.43
A21: Director Remuneration | B21: =SUMIF('4. Category Summary'!A5:A49,"Director Remuneration",'4. Category Summary'!E5:E49) -> 25040 | C21: Must be on PAYE
A22: Staff Costs (Stipends/Benefits/Training) | B22: =SUMIF('4. Category Summary'!A5:A49,"Staff Costs - Stipend",'4. Category Summary'!E5:E49)+SUMIF('4. Category Summary'!A5:A49,"Staff Costs - Benefits",'4. Category Summary'!E5:E49)+SUMIF('4. Category Summary'!A5:A49,"Staff Costs - Training",'4. Category Summary'!E5:E49)+SUMIF('4. Category Summary'!A5:A49,"Staff Costs - Reimbursement",'4. Category Summary'!E5:E49) -> 96471.5 | C22: Review IRP5 obligations
A23: TOTAL OPERATING EXPENSES | B23: ='4. Category Summary'!E50 -> 376689.73 | C23: From '4. Category Summary' (master total)
A25: LESS: WEAR-AND-TEAR (DEPRECIATION) | B25: ='6. Asset Register'!H30 -> 75102.833 | C25: From Asset Register
A27: TAXABLE INCOME | B27: =B8-B23-B25 -> 60062.277 | C27: Income less expenses less depreciation
A29: CORPORATE INCOME TAX @ 27% | B29: =IF(B27>0,B27*0.27,0) -> 16216.815 | C29: Standard CIT rate FY 2025/26
A31: LESS: Provisional Tax Already Paid | B31: 0 | C31: FILL IN — IRP6 payments
A33: TAX PAYABLE / (REFUND) | B33: =B29-B31 -> 16216.815
A37: SMALL BUSINESS CORPORATION (SBC) SCENARIO — POTENTIAL HUGE SAVING
A38: Pty Ltd qualifying as SBC pays 0% tax on first R95,750 — your taxable income may fall entirely in the 0% bracket. Check eligibility: (a) all members natural persons, (b) gross income ≤ R20m, (c) ≤20% income from investments/personal services, (d) not a personal service provider.
A40: SBC Tax Bands (Y/A 2026) | B40: Rate
A41: R0 – R95,750 | B41: 0%
A42: R95,751 – R365,000 | B42: 7% above R95,750
A43: R365,001 – R550,000 | B43: R18,848 + 21% above R365,000
A44: Above R550,000 | B44: R57,698 + 27% above R550,000
A46: SBC Tax on YOUR taxable income | B46: =IF(B27<=0,0,IF(B27<=95750,0,IF(B27<=365000,(B27-95750)*0.07,IF(B27<=550000,18848+(B27-365000)*0.21,57698+(B27-550000)*0.27)))) -> 0
A47: Standard CIT Tax (27% flat) | B47: =B29 -> 16216.815 | C47: From row 29 above
A48: POTENTIAL TAX SAVING IF SBC | B48: =B47-B45 -> 16216.815 | C48: Confirm SBC eligibility with your accountant

Sheet 10. SARS Checklist
A1: SARS COMPLIANCE CHECKLIST — 2025/2026 Year of Assessment
A3: Task | B3: Deadline | C3: Status | D3: Notes
A4: PROVISIONAL TAX | D4: Required for Pty Ltd
A5: First Provisional Tax (IRP6) | B5: 31 August 2025 | C5: PAST | D5: If missed, penalties may apply
A6: Second Provisional Tax (IRP6) | B6: 28 February 2026 | C6: DUE | D6: Based on actual estimates
A7: Third Top-up (Voluntary) | B7: 30 September 2026 | C7: Future | D7: To avoid 7.5% interest on shortfall
A9: ANNUAL FILINGS
A10: Income Tax Return ITR14 | B10: 28 February 2027 (12 months after YE) | C10: Future | D10: Pty Ltd corporate tax return
A11: Annual Financial Statements (AFS) | B11: Within 6 months of YE | C11: Future | D11: Required for Pty Ltd
A12: CIPC Annual Return | B12: Anniversary of incorporation | C12: Check | D12: R100 fee paid May 2025 ✓
A14: PAYE / EMP201 | D14: If you pay salaries
A15: Monthly EMP201 returns | B15: 7th of following month | C15: Monthly | D15: Director Salary R25,000 — needs PAYE if > tax threshold
A16: EMP501 Reconciliation (interim) | B16: 31 October 2025 | C16: PAST | D16: If registered for PAYE
A17: EMP501 Reconciliation (annual) | B17: 31 May 2026 | C17: DUE | D17: Submit IRP5/IT3(a) certificates
A19: VAT (only if registered) | D19: Required if turnover > R1m/yr — your turnover is below
A20: VAT201 returns | B20: Bi-monthly or monthly | C20: Check status | D20: You appear NOT registered
A22: DOCUMENTS TO KEEP (5 years)
A23: Bank statements | B23: Whole period | C23: ✓ Have these | D23: 12 statements covered
A24: Tax invoices for all expenses | B24: Each transaction | C24: INCOMPLETE | D24: See Missing Receipts sheet
A25: Vehicle logbook | B25: Full year | C25: MISSING | D25: Critical — fill in sheet 5
A26: Director Resolutions (salaries, etc.) | B26: When paid | C26: Check | D26: For director remuneration
A27: Loan agreements (if any) | B27: When signed | C27: Check | D27: R65,500 loan repayment seen
A28: Asset purchase invoices | B28: When acquired | C28: Check | D28: For depreciation claims
A29: Trip records (purpose, attendees) | B29: Per trip | C29: INCOMPLETE | D29: See Trips sheet
